Workbook

Sheet Getting Started
B2: How to Setup This Transcript
B3: FALSE | C3: Make a copy of this spreadsheet by clicking this link and then clicking "Make a copy"
B4: FALSE | C4: Fill in the header information below this section to the right. This information will be automatically attached to all of the headers throughout this transcript
B5: FALSE | C5: Fill in the "Grading Period" cell in the spreadsheet controls (below this section, to the left). This controls whether the transcript will be separated by year, semester, trimester, or quarter
F8: Header Information
F9: Student Information | H9: School Information
B10: Spreadsheet Controls | F10: Full Name | H10: Name
B11: Grading Period | F11: Date of Birth | H11: Phone Number
F12: Parent/Guardian | H12: Address
F14: Expected Graduation | H14: Email Address
B17: How to Use This Transcript
B18: How to use the Grade Sheets | F18: How to use the 'Books' and 'Leadership Roles & Awards' Sheets
B19: Switch between this sheet and the different grade sheets (e.g. "1st Grade (Year)" and "3rd Grade (Trimester)") by clicking the tabs at the bottom of your browser window You can change the grade scale of each sheet by looking in the top left corner for the "Grade Scale" cell By clicking the dropdown, you can choose between 0-4, 0-100, Letter, and None, which will adapt the sheet to your needs If you select the 0-4, 0-100, or Letter grade scale, the sheet will automatically calculate your Grade Point Average and also your total credits To print your transcript, press and hold the Control (or "Ctrl") key and press the P key This transcript is designed for Letter paper | F19: These sheets are to help you track additional information that is often requested along with a transcript. Switch between this sheet and the 'Books' and 'Leadership Roles & Awards' sheets by clicking the tabs at the bottom of your browser window Fill in the books your child has read, the leadership roles they have held, and the leadership awards they have received by entering them into each row To print your transcript, press and hold the Control (or "Ctrl") key and press the P key This transcript is designed for Letter paper

Sheet Books
B1: Student Information | D1: School Information
B2: Full Name | C2: ='Getting Started'!$G$10 | D2: Name | E2: ='Getting Started'!$I$10
B3: Date of Birth | C3: ='Getting Started'!$G$11 | D3: Phone Number | E3: ='Getting Started'!$I$11
B4: Parent/Guardian | C4: ='Getting Started'!$G$12 | D4: Address | E4: ='Getting Started'!$I$12
B5: Expected Graduation | C5: ='Getting Started'!$G$14 | D5: Email Address | E5: ='Getting Started'!$I$14
B6: Title | C6: Author | D6: Grade Read | E6: Lexile Level
A26: 1
B28: Student Information | D28: School Information
B29: Full Name | C29: ='Getting Started'!$G$10 | D29: Name | E29: ='Getting Started'!$I$10
B30: Date of Birth | C30: ='Getting Started'!$G$11 | D30: Phone Number | E30: ='Getting Started'!$I$11
B31: Parent/Guardian | C31: ='Getting Started'!$G$12 | D31: Address | E31: ='Getting Started'!$I$12
B32: Expected Graduation | C32: ='Getting Started'!$G$14 | D32: Email Address | E32: ='Getting Started'!$I$14
B33: Title | C33: Author | D33: Grade Read | E33: Lexile Level
A53: 2
B55: Student Information | D55: School Information
B56: Full Name | C56: ='Getting Started'!$G$10 | D56: Name | E56: ='Getting Started'!$I$10
B57: Date of Birth | C57: ='Getting Started'!$G$11 | D57: Phone Number | E57: ='Getting Started'!$I$11
B58: Parent/Guardian | C58: ='Getting Started'!$G$12 | D58: Address | E58: ='Getting Started'!$I$12
B59: Expected Graduation | C59: ='Getting Started'!$G$14 | D59: Email Address | E59: ='Getting Started'!$I$14
B60: Title | C60: Author | D60: Grade Read | E60: Lexile Level
A80: 3
B82: Student Information | D82: School Information
B83: Full Name | C83: ='Getting Started'!$G$10 | D83: Name | E83: ='Getting Started'!$I$10
B84: Date of Birth | C84: ='Getting Started'!$G$11 | D84: Phone Number | E84: ='Getting Started'!$I$11
B85: Parent/Guardian | C85: ='Getting Started'!$G$12 | D85: Address | E85: ='Getting Started'!$I$12
B86: Expected Graduation | C86: ='Getting Started'!$G$14 | D86: Email Address | E86: ='Getting Started'!$I$14
B87: Title | C87: Author | D87: Grade Read | E87: Lexile Level
A107: 4
B109: Student Information | D109: School Information
B110: Full Name | C110: ='Getting Started'!$G$10 | D110: Name | E110: ='Getting Started'!$I$10
B111: Date of Birth | C111: ='Getting Started'!$G$11 | D111: Phone Number | E111: ='Getting Started'!$I$11
B112: Parent/Guardian | C112: ='Getting Started'!$G$12 | D112: Address | E112: ='Getting Started'!$I$12
B113: Expected Graduation | C113: ='Getting Started'!$G$14 | D113: Email Address | E113: ='Getting Started'!$I$14
B114: Title | C114: Author | D114: Grade Read | E114: Lexile Level
A134: 5
B136: Student Information | D136: School Information
B137: Full Name | C137: ='Getting Started'!$G$10 | D137: Name | E137: ='Getting Started'!$I$10
B138: Date of Birth | C138: ='Getting Started'!$G$11 | D138: Phone Number | E138: ='Getting Started'!$I$11
B139: Parent/Guardian | C139: ='Getting Started'!$G$12 | D139: Address | E139: ='Getting Started'!$I$12
B140: Expected Graduation | C140: ='Getting Started'!$G$14 | D140: Email Address | E140: ='Getting Started'!$I$14
...

Sheet Leadership Roles & Awards
B1: Student Information | D1: School Information
B2: Full Name | C2: ='Getting Started'!$G$10 | D2: Name | E2: ='Getting Started'!$I$10
B3: Date of Birth | C3: ='Getting Started'!$G$11 | D3: Phone Number | E3: ='Getting Started'!$I$11
B4: Parent/Guardian | C4: ='Getting Started'!$G$12 | D4: Address | E4: ='Getting Started'!$I$12
B5: Expected Graduation | C5: ='Getting Started'!$G$14 | D5: Email Address | E5: ='Getting Started'!$I$14
B6: Role/Award | C6: Organization | D6: Date Start | E6: Date End
A26: 1
B28: Student Information | D28: School Information
B29: Full Name | C29: ='Getting Started'!$G$10 | D29: Name | E29: ='Getting Started'!$I$10
B30: Date of Birth | C30: ='Getting Started'!$G$11 | D30: Phone Number | E30: ='Getting Started'!$I$11
B31: Parent/Guardian | C31: ='Getting Started'!$G$12 | D31: Address | E31: ='Getting Started'!$I$12
B32: Expected Graduation | C32: ='Getting Started'!$G$14 | D32: Email Address | E32: ='Getting Started'!$I$14
B33: Role/Award | C33: Organization | D33: Date Start | E33: Date End
A53: 2
B55: Student Information | D55: School Information
B56: Full Name | C56: ='Getting Started'!$G$10 | D56: Name | E56: ='Getting Started'!$I$10
B57: Date of Birth | C57: ='Getting Started'!$G$11 | D57: Phone Number | E57: ='Getting Started'!$I$11
B58: Parent/Guardian | C58: ='Getting Started'!$G$12 | D58: Address | E58: ='Getting Started'!$I$12
B59: Expected Graduation | C59: ='Getting Started'!$G$14 | D59: Email Address | E59: ='Getting Started'!$I$14
B60: Role/Award | C60: Organization | D60: Date Start | E60: Date End
A80: 3
B82: Student Information | D82: School Information
B83: Full Name | C83: ='Getting Started'!$G$10 | D83: Name | E83: ='Getting Started'!$I$10
B84: Date of Birth | C84: ='Getting Started'!$G$11 | D84: Phone Number | E84: ='Getting Started'!$I$11
B85: Parent/Guardian | C85: ='Getting Started'!$G$12 | D85: Address | E85: ='Getting Started'!$I$12
B86: Expected Graduation | C86: ='Getting Started'!$G$14 | D86: Email Address | E86: ='Getting Started'!$I$14
B87: Role/Award | C87: Organization | D87: Date Start | E87: Date End
A107: 4
B109: Student Information | D109: School Information
B110: Full Name | C110: ='Getting Started'!$G$10 | D110: Name | E110: ='Getting Started'!$I$10
B111: Date of Birth | C111: ='Getting Started'!$G$11 | D111: Phone Number | E111: ='Getting Started'!$I$11
B112: Parent/Guardian | C112: ='Getting Started'!$G$12 | D112: Address | E112: ='Getting Started'!$I$12
B113: Expected Graduation | C113: ='Getting Started'!$G$14 | D113: Email Address | E113: ='Getting Started'!$I$14
B114: Role/Award | C114: Organization | D114: Date Start | E114: Date End
A134: 5
B136: Student Information | D136: School Information
B137: Full Name | C137: ='Getting Started'!$G$10 | D137: Name | E137: ='Getting Started'!$I$10
B138: Date of Birth | C138: ='Getting Started'!$G$11 | D138: Phone Number | E138: ='Getting Started'!$I$11
B139: Parent/Guardian | C139: ='Getting Started'!$G$12 | D139: Address | E139: ='Getting Started'!$I$12
B140: Expected Graduation | C140: ='Getting Started'!$G$14 | D140: Email Address | E140: ='Getting Started'!$I$14
...

Sheet Kindergarten (Year)
C1: Student Information | I1: School Information
B2: Grade Scale | C2: Full Name | F2: ='Getting Started'!$G$10 | I2: Name | K2: ='Getting Started'!$I$10
B3: 0-4 | C3: Date of Birth | F3: ='Getting Started'!$G$11 | I3: Phone Number | K3: ='Getting Started'!$I$11
C4: Parent/Guardian | F4: ='Getting Started'!$G$12 | I4: Address | K4: ='Getting Started'!$I$12
C5: Expected Graduation | F5: ='Getting Started'!$G$14 | I5: Email Address | K5: ='Getting Started'!$I$14
B6: Classes
B7: Course Title | K7: Credits | L7: Met Requirements | M7: Grade | O7: Weight
L8: FALSE
L9: FALSE
L10: FALSE
L11: FALSE
L12: FALSE
L13: FALSE
L14: FALSE
L15: FALSE
L16: FALSE
L17: FALSE
L18: FALSE
L19: FALSE
... L49: FALSE
B51: MAP Scores | J51: Cumulative
B52: Subject | C52: RIT Score | F52: Percentile | J52: Grade Point Average | M52: Total Credits
C53: Spring | D53: Fall | E53: Winter | F53: Spring | G53: Fall | H53: Winter | J53: {=GPA({$K$8:$K$49,$M$8:$M$49,$O$8:$O$49},1,2)} -> Loading... | M53: {=CREDITSSUM({$K$8:$K$49,$M$8:$M$49},1,2)} -> Loading...
B54: Math
B55: Reading

Sheet 1st Grade (Year)
C1: Student Information | I1: School Information
B2: Grade Scale | C2: Full Name | F2: ='Getting Started'!$G$10 | I2: Name | K2: ='Getting Started'!$I$10
B3: 0-4 | C3: Date of Birth | F3: ='Getting Started'!$G$11 | I3: Phone Number | K3: ='Getting Started'!$I$11
C4: Parent/Guardian | F4: ='Getting Started'!$G$12 | I4: Address | K4: ='Getting Started'!$I$12
C5: Expected Graduation | F5: ='Getting Started'!$G$14 | I5: Email Address | K5: ='Getting Started'!$I$14
B6: Classes
B7: Course Title | K7: Credits | L7: Met Requirements | M7: Grade | O7: Weight
L8: FALSE
L9: FALSE
L10: FALSE
L11: FALSE
L12: FALSE
L13: FALSE
L14: FALSE
L15: FALSE
L16: FALSE
L17: FALSE
L18: FALSE
L19: FALSE
... L49: FALSE
B51: MAP Scores | J51: Cumulative
B52: Subject | C52: RIT Score | F52: Percentile | J52: Grade Point Average | M52: Total Credits
C53: Spring | D53: Fall | E53: Winter | F53: Spring | G53: Fall | H53: Winter | J53: {=GPA({$K$8:$K$49,$M$8:$M$49,$O$8:$O$49},1,2)} -> Loading... | M53: {=CREDITSSUM({$K$8:$K$49,$M$8:$M$49},1,2)} -> Loading...
B54: Math
B55: Reading

Sheet 2nd Grade (Year)
C1: Student Information | I1: School Information
B2: Grade Scale | C2: Full Name | F2: ='Getting Started'!$G$10 | I2: Name | K2: ='Getting Started'!$I$10
B3: 0-4 | C3: Date of Birth | F3: ='Getting Started'!$G$11 | I3: Phone Number | K3: ='Getting Started'!$I$11
C4: Parent/Guardian | F4: ='Getting Started'!$G$12 | I4: Address | K4: ='Getting Started'!$I$12
C5: Expected Graduation | F5: ='Getting Started'!$G$14 | I5: Email Address | K5: ='Getting Started'!$I$14
B6: Classes
B7: Course Title | K7: Credits | L7: Met Requirements | M7: Grade | O7: Weight
L8: FALSE
L9: FALSE
L10: FALSE
L11: FALSE
L12: FALSE
L13: FALSE
L14: FALSE
L15: FALSE
L16: FALSE
L17: FALSE
L18: FALSE
L19: FALSE
... L49: FALSE
B51: MAP Scores | J51: Cumulative
B52: Subject | C52: RIT Score | F52: Percentile | J52: Grade Point Average | M52: Total Credits
C53: Spring | D53: Fall | E53: Winter | F53: Spring | G53: Fall | H53: Winter | J53: {=GPA({$K$8:$K$49,$M$8:$M$49,$O$8:$O$49},1,2)} -> Loading... | M53: {=CREDITSSUM({$K$8:$K$49,$M$8:$M$49},1,2)} -> Loading...
B54: Math
B55: Reading

Sheet 3rd Grade (Year)
C1: Student Information | I1: School Information
B2: Grade Scale | C2: Full Name | F2: ='Getting Started'!$G$10 | I2: Name | K2: ='Getting Started'!$I$10
B3: 0-4 | C3: Date of Birth | F3: ='Getting Started'!$G$11 | I3: Phone Number | K3: ='Getting Started'!$I$11
C4: Parent/Guardian | F4: ='Getting Started'!$G$12 | I4: Address | K4: ='Getting Started'!$I$12
C5: Expected Graduation | F5: ='Getting Started'!$G$14 | I5: Email Address | K5: ='Getting Started'!$I$14
B6: Classes
B7: Course Title | K7: Credits | L7: Met Requirements | M7: Grade | O7: Weight
L8: FALSE
L9: FALSE
L10: FALSE
L11: FALSE
L12: FALSE
L13: FALSE
L14: FALSE
L15: FALSE
L16: FALSE
L17: FALSE
L18: FALSE
L19: FALSE
... L49: FALSE
B51: MAP Scores | J51: Cumulative
B52: Subject | C52: RIT Score | F52: Percentile | J52: Grade Point Average | M52: Total Credits
C53: Spring | D53: Fall | E53: Winter | F53: Spring | G53: Fall | H53: Winter | J53: {=GPA({$K$8:$K$49,$M$8:$M$49,$O$8:$O$49},1,2)} -> Loading... | M53: {=CREDITSSUM({$K$8:$K$49,$M$8:$M$49},1,2)} -> Loading...
B54: Math
B55: Reading
B56: Language Usage
B57: Science

Sheet 4th Grade (Year)
C1: Student Information | I1: School Information
B2: Grade Scale | C2: Full Name | F2: ='Getting Started'!$G$10 | I2: Name | K2: ='Getting Started'!$I$10
B3: 0-4 | C3: Date of Birth | F3: ='Getting Started'!$G$11 | I3: Phone Number | K3: ='Getting Started'!$I$11
C4: Parent/Guardian | F4: ='Getting Started'!$G$12 | I4: Address | K4: ='Getting Started'!$I$12
C5: Expected Graduation | F5: ='Getting Started'!$G$14 | I5: Email Address | K5: ='Getting Started'!$I$14
B6: Classes
B7: Course Title | K7: Credits | L7: Met Requirements | M7: Grade | O7: Weight
L8: FALSE
L9: FALSE
L10: FALSE
L11: FALSE
L12: FALSE
L13: FALSE
L14: FALSE
L15: FALSE
L16: FALSE
L17: FALSE
L18: FALSE
L19: FALSE
... L49: FALSE
B51: MAP Scores | J51: Cumulative
B52: Subject | C52: RIT Score | F52: Percentile | J52: Grade Point Average | M52: Total Credits
C53: Spring | D53: Fall | E53: Winter | F53: Spring | G53: Fall | H53: Winter | J53: {=GPA({$K$8:$K$49,$M$8:$M$49,$O$8:$O$49},1,2)} -> Loading... | M53: {=CREDITSSUM({$K$8:$K$49,$M$8:$M$49},1,2)} -> Loading...
B54: Math
B55: Reading
B56: Language Usage
B57: Science

Sheet 5th Grade (Year)
C1: Student Information | I1: School Information
B2: Grade Scale | C2: Full Name | F2: ='Getting Started'!$G$10 | I2: Name | K2: ='Getting Started'!$I$10
B3: 0-4 | C3: Date of Birth | F3: ='Getting Started'!$G$11 | I3: Phone Number | K3: ='Getting Started'!$I$11
C4: Parent/Guardian | F4: ='Getting Started'!$G$12 | I4: Address | K4: ='Getting Started'!$I$12
C5: Expected Graduation | F5: ='Getting Started'!$G$14 | I5: Email Address | K5: ='Getting Started'!$I$14
B6: Classes
B7: Course Title | K7: Credits | L7: Met Requirements | M7: Grade | O7: Weight
L8: FALSE
L9: FALSE
L10: FALSE
L11: FALSE
L12: FALSE
L13: FALSE
L14: FALSE
L15: FALSE
L16: FALSE
L17: FALSE
L18: FALSE
L19: FALSE
... L49: FALSE
B51: MAP Scores | J51: Cumulative
B52: Subject | C52: RIT Score | F52: Percentile | J52: Grade Point Average | M52: Total Credits
C53: Spring | D53: Fall | E53: Winter | F53: Spring | G53: Fall | H53: Winter | J53: {=GPA({$K$8:$K$49,$M$8:$M$49,$O$8:$O$49},1,2)} -> Loading... | M53: {=CREDITSSUM({$K$8:$K$49,$M$8:$M$49},1,2)} -> Loading...
B54: Math
B55: Reading
B56: Language Usage
B57: Science

Sheet 6th Grade (Year)
C1: Student Information | I1: School Information
B2: Grade Scale | C2: Full Name | F2: ='Getting Started'!$G$10 | I2: Name | K2: ='Getting Started'!$I$10
B3: 0-4 | C3: Date of Birth | F3: ='Getting Started'!$G$11 | I3: Phone Number | K3: ='Getting Started'!$I$11
C4: Parent/Guardian | F4: ='Getting Started'!$G$12 | I4: Address | K4: ='Getting Started'!$I$12
C5: Expected Graduation | F5: ='Getting Started'!$G$14 | I5: Email Address | K5: ='Getting Started'!$I$14
B6: Classes
B7: Course Title | K7: Credits | L7: Met Requirements | M7: Grade | O7: Weight
L8: FALSE
L9: FALSE
L10: FALSE
L11: FALSE
L12: FALSE
L13: FALSE
L14: FALSE
L15: FALSE
L16: FALSE
L17: FALSE
L18: FALSE
L19: FALSE
... L49: FALSE
B51: MAP Scores | J51: Cumulative
B52: Subject | C52: RIT Score | F52: Percentile | J52: Grade Point Average | M52: Total Credits
C53: Spring | D53: Fall | E53: Winter | F53: Spring | G53: Fall | H53: Winter | J53: {=GPA({$K$8:$K$49,$M$8:$M$49,$O$8:$O$49},1,2)} -> Loading... | M53: {=CREDITSSUM({$K$8:$K$49,$M$8:$M$49},1,2)} -> Loading...
B54: Math
B55: Reading
B56: Language Usage
B57: Science

Sheet 7th Grade (Year)
C1: Student Information | I1: School Information
B2: Grade Scale | C2: Full Name | F2: ='Getting Started'!$G$10 | I2: Name | K2: ='Getting Started'!$I$10
B3: 0-4 | C3: Date of Birth | F3: ='Getting Started'!$G$11 | I3: Phone Number | K3: ='Getting Started'!$I$11
C4: Parent/Guardian | F4: ='Getting Started'!$G$12 | I4: Address | K4: ='Getting Started'!$I$12
C5: Expected Graduation | F5: ='Getting Started'!$G$14 | I5: Email Address | K5: ='Getting Started'!$I$14
B6: Classes
B7: Course Title | K7: Credits | L7: Met Requirements | M7: Grade | O7: Weight
L8: FALSE
L9: FALSE
L10: FALSE
L11: FALSE
L12: FALSE
L13: FALSE
L14: FALSE
L15: FALSE
L16: FALSE
L17: FALSE
L18: FALSE
L19: FALSE
... L49: FALSE
B51: MAP Scores | J51: Cumulative
B52: Subject | C52: RIT Score | F52: Percentile | J52: Grade Point Average | M52: Total Credits
C53: Spring | D53: Fall | E53: Winter | F53: Spring | G53: Fall | H53: Winter | J53: {=GPA({$K$8:$K$49,$M$8:$M$49,$O$8:$O$49},1,2)} -> Loading... | M53: {=CREDITSSUM({$K$8:$K$49,$M$8:$M$49},1,2)} -> Loading...
B54: Math
B55: Reading
B56: Language Usage
B57: Science

Sheet 8th Grade (Year)
C1: Student Information | I1: School Information
B2: Grade Scale | C2: Full Name | F2: ='Getting Started'!$G$10 | I2: Name | K2: ='Getting Started'!$I$10
B3: 0-4 | C3: Date of Birth | F3: ='Getting Started'!$G$11 | I3: Phone Number | K3: ='Getting Started'!$I$11
C4: Parent/Guardian | F4: ='Getting Started'!$G$12 | I4: Address | K4: ='Getting Started'!$I$12
C5: Expected Graduation | F5: ='Getting Started'!$G$14 | I5: Email Address | K5: ='Getting Started'!$I$14
B6: Classes
B7: Course Title | K7: Credits | L7: Met Requirements | M7: Grade | O7: Weight
L8: FALSE
L9: FALSE
L10: FALSE
L11: FALSE
L12: FALSE
L13: FALSE
L14: FALSE
L15: FALSE
L16: FALSE
L17: FALSE
L18: FALSE
L19: FALSE
... L49: FALSE
B51: MAP Scores | J51: Cumulative
B52: Subject | C52: RIT Score | F52: Percentile | J52: Grade Point Average | M52: Total Credits
C53: Spring | D53: Fall | E53: Winter | F53: Spring | G53: Fall | H53: Winter | J53: {=GPA({$K$8:$K$49,$M$8:$M$49,$O$8:$O$49},1,2)} -> Loading... | M53: {=CREDITSSUM({$K$8:$K$49,$M$8:$M$49},1,2)} -> Loading...
B54: Math
B55: Reading
B56: Language Usage
B57: Science

Sheet 9th Grade (Year)
C1: Student Information | I1: School Information
B2: Grade Scale
B3: 0-4 | C3: Full Name | F3: ='Getting Started'!$G$10 | I3: Name | K3: ='Getting Started'!$I$10
B4: Cumulative GPA | C4: Date of Birth | F4: ='Getting Started'!$G$11 | I4: Phone Number | K4: ='Getting Started'!$I$11
B5: =J55 -> Loading... | C5: Parent/Guardian | F5: ='Getting Started'!$G$12 | I5: Address | K5: ='Getting Started'!$I$12
B6: Total Credits
B7: =M55 -> Loading... | C7: Expected Graduation | F7: ='Getting Started'!$G$14 | I7: Email Address | K7: ='Getting Started'!$I$14
B8: Classes
B9: Course Title | K9: Credits | L9: Met Requirements | M9: Grade | O9: Weight
L11: FALSE
L12: FALSE
L13: FALSE
L14: FALSE
L15: FALSE
L16: FALSE
L17: FALSE
L18: FALSE
L19: FALSE
L20: FALSE
L21: FALSE
L22: FALSE
... L51: FALSE
B53: MAP Scores | J53: Cumulative
B54: Subject | C54: RIT Score | F54: Percentile | J54: Grade Point Average | M54: Total Credits
C55: Spring | D55: Fall | E55: Winter | F55: Spring | G55: Fall | H55: Winter | J55: {=GPA({$K$10:$K$51,$M$10:$M$51,$O$10:$O$51},1,2)} -> Loading... | M55: {=CREDITSSUM({$K$10:$K$51,$M$10:$M$51},1,2)} -> Loading...
B56: Math | I56: Notes
B57: Reading
B58: Language Usage
B59: Science

Sheet 10th Grade (Year)
C1: Student Information | I1: School Information
B2: Grade Scale
B3: 0-4 | C3: Full Name | F3: ='Getting Started'!$G$10 | I3: Name | K3: ='Getting Started'!$I$10
B4: Cumulative GPA | C4: Date of Birth | F4: ='Getting Started'!$G$11 | I4: Phone Number | K4: ='Getting Started'!$I$11
B5: {=GPA({'9th Grade (Year)'!$K$10:$K$51,'9th Grade (Year)'!$M$10:$M$51,'9th Grade (Year)'!$O$10:$O$51;$K$10:$K$51,$M$10:$M$51,$O$10:$O$51},1,2)} -> Loading... | C5: Parent/Guardian | F5: ='Getting Started'!$G$12 | I5: Address | K5: ='Getting Started'!$I$12
B6: Total Credits
B7: =IF('9th Grade (Year)'!B7+M55 = 0, "", '9th Grade (Year)'!B7+M55) -> Loading... | C7: Expected Graduation | F7: ='Getting Started'!$G$14 | I7: Email Address | K7: ='Getting Started'!$I$14
B8: Classes
B9: Course Title | K9: Credits | L9: Met Requirements | M9: Grade | O9: Weight
L10: FALSE
L11: FALSE
L12: FALSE
L13: FALSE
L14: FALSE
L15: FALSE
L16: FALSE
L17: FALSE
L18: FALSE
L19: FALSE
L20: FALSE
L21: FALSE
... L51: FALSE
B53: MAP Scores | J53: Cumulative
B54: Subject | C54: RIT Score | F54: Percentile | J54: Grade Point Average | M54: Total Credits
C55: Spring | D55: Fall | E55: Winter | F55: Spring | G55: Fall | H55: Winter | J55: {=GPA({$K$10:$K$51,$M$10:$M$51,$O$10:$O$51},1,2)} -> Loading... | M55: {=CREDITSSUM({$K$10:$K$51,$M$10:$M$51},1,2)} -> Loading...
B56: Math | I56: Notes
B57: Reading
B58: Language Usage
B59: Science

Sheet 11th Grade (Year)
C1: Student Information | I1: School Information
B2: Grade Scale
B3: 0-4 | C3: Full Name | F3: ='Getting Started'!$G$10 | I3: Name | K3: ='Getting Started'!$I$10
B4: Cumulative GPA | C4: Date of Birth | F4: ='Getting Started'!$G$11 | I4: Phone Number | K4: ='Getting Started'!$I$11
B5: {=GPA({'9th Grade (Year)'!$K$10:$K$51,'9th Grade (Year)'!$M$10:$M$51,'9th Grade (Year)'!$O$10:$O$51;'10th Grade (Year)'!$K$10:$K$51,'10th Grade (Year)'!$M$10:$M$51,'10th Grade (Year)'!$O$10:$O$51;$K$10:$K$51,$M$10:$M$51,$O$10:$O$51},1,2)} -> Loading... | C5: Parent/Guardian | F5: ='Getting Started'!$G$12 | I5: Address | K5: ='Getting Started'!$I$12
B6: Total Credits
B7: =IF('10th Grade (Year)'!B7+M55 = 0, "", '10th Grade (Year)'!B7+M55) -> Loading... | C7: Expected Graduation | F7: ='Getting Started'!$G$14 | I7: Email Address | K7: ='Getting Started'!$I$14
B8: Classes
B9: Course Title | K9: Credits | L9: Met Requirements | M9: Grade | O9: Weight
L10: FALSE
L11: FALSE
L12: FALSE
L13: FALSE
L14: FALSE
L15: FALSE
L16: FALSE
L17: FALSE
L18: FALSE
L19: FALSE
L20: FALSE
L21: FALSE
... L51: FALSE
B53: MAP Scores | J53: Cumulative
B54: Subject | C54: RIT Score | F54: Percentile | J54: Grade Point Average | M54: Total Credits
C55: Spring | D55: Fall | E55: Winter | F55: Spring | G55: Fall | H55: Winter | J55: {=GPA({$K$10:$K$51,$M$10:$M$51,$O$10:$O$51},1,2)} -> Loading... | M55: {=CREDITSSUM({$K$10:$K$51,$M$10:$M$51},1,2)} -> Loading...
B56: Math | I56: Notes
B57: Reading
B58: Language Usage
B59: Science

Sheet 12th Grade (Year)
C1: Student Information | I1: School Information
B2: Grade Scale
B3: 0-4 | C3: Full Name | F3: ='Getting Started'!$G$10 | I3: Name | K3: ='Getting Started'!$I$10
B4: Cumulative GPA | C4: Date of Birth | F4: ='Getting Started'!$G$11 | I4: Phone Number | K4: ='Getting Started'!$I$11
B5: {=GPA({'9th Grade (Year)'!$K$10:$K$51,'9th Grade (Year)'!$M$10:$M$51,'9th Grade (Year)'!$O$10:$O$51;'10th Grade (Year)'!$K$10:$K$51,'10th Grade (Year)'!$M$10:$M$51,'10th Grade (Year)'!$O$10:$O$51;'11th Grade (Year)'!$K$10:$K$51,'11th Grade (Year)'!$M$10:$M$51,'11th Grade (Year)'!$O$10:$O$51;$K$10:$K$51,$M$10:$M$51,$O$10:$O$51},1,2)} -> Loading... | C5: Parent/Guardian | F5: ='Getting Started'!$G$12 | I5: Address | K5: ='Getting Started'!$I$12
B6: Total Credits
B7: =IF('11th Grade (Year)'!B7+M55 = 0, "", '11th Grade (Year)'!B7+M55) -> Loading... | C7: Expected Graduation | F7: ='Getting Started'!$G$14 | I7: Email Address | K7: ='Getting Started'!$I$14
B8: Classes
B9: Course Title | K9: Credits | L9: Met Requirements | M9: Grade | O9: Weight
L12: FALSE
L13: FALSE
L14: FALSE
L15: FALSE
L16: FALSE
L17: FALSE
L18: FALSE
L19: FALSE
L20: FALSE
L21: FALSE
L22: FALSE
L23: FALSE
... L51: FALSE
B53: MAP Scores | J53: Cumulative
B54: Subject | C54: RIT Score | F54: Percentile | J54: Grade Point Average | M54: Total Credits
C55: Spring | D55: Fall | E55: Winter | F55: Spring | G55: Fall | H55: Winter | J55: {=GPA({$K$10:$K$51,$M$10:$M$51,$O$10:$O$51},1,2)} -> Loading... | M55: {=CREDITSSUM({$K$10:$K$51,$M$10:$M$51},1,2)} -> Loading...
B56: Math | I56: Notes
B57: Reading
B58: Language Usage
B59: Science

Sheet Kindergarten (Semester)
C1: Student Information | I1: School Information
B2: Grade Scale | C2: Full Name | F2: ='Getting Started'!$G$10 | I2: Name | K2: ='Getting Started'!$I$10
B3: 0-4 | C3: Date of Birth | F3: ='Getting Started'!$G$11 | I3: Phone Number | K3: ='Getting Started'!$I$11
C4: Parent/Guardian | F4: ='Getting Started'!$G$12 | I4: Address | K4: ='Getting Started'!$I$12
C5: Expected Graduation | F5: ='Getting Started'!$G$14 | I5: Email Address | K5: ='Getting Started'!$I$14
B6: Classes (Semester 1)
B7: Course Title | K7: Credits | L7: Met Requirements | M7: Grade | O7: Weight
L9: FALSE
L10: FALSE
L11: FALSE
L12: FALSE
L13: FALSE
L14: FALSE
L15: FALSE
L16: FALSE
L17: FALSE
L18: FALSE
L19: FALSE
L20: FALSE
... L25: FALSE
J26: Cumulative (Semester 1)
J27: Grade Point Average | M27: Total Credits
B28: Classes (Semester 2) | J28: {=GPA({K8:K25,M8:M25,O8:O25},1,2)} -> Loading... | M28: {=CREDITSSUM({K8:K25,M8:M25},1,2)} -> Loading...
B29: Course Title | K29: Credits | L29: Met Requirements | M29: Grade | O29: Weight
L31: FALSE
L32: FALSE
L33: FALSE
L34: FALSE
L35: FALSE
L36: FALSE
L37: FALSE
L38: FALSE
L39: FALSE
L40: FALSE
L41: FALSE
L42: FALSE
... L47: FALSE
J48: Cumulative (Semester 2)
J49: Grade Point Average | M49: Total Credits
B50: MAP Scores | J50: {=GPA({K30:K47,M30:M47,O30:O47},1,2)} -> Loading... | M50: {=CREDITSSUM({K30:K47,M30:M47},1,2)} -> Loading...
...

Sheet 1st Grade (Semester)
C1: Student Information | I1: School Information
B2: Grade Scale | C2: Full Name | F2: ='Getting Started'!$G$10 | I2: Name | K2: ='Getting Started'!$I$10
B3: 0-4 | C3: Date of Birth | F3: ='Getting Started'!$G$11 | I3: Phone Number | K3: ='Getting Started'!$I$11
C4: Parent/Guardian | F4: ='Getting Started'!$G$12 | I4: Address | K4: ='Getting Started'!$I$12
C5: Expected Graduation | F5: ='Getting Started'!$G$14 | I5: Email Address | K5: ='Getting Started'!$I$14
B6: Classes (Semester 1)
B7: Course Title | K7: Credits | L7: Met Requirements | M7: Grade | O7: Weight
L9: FALSE
L10: FALSE
L11: FALSE
L12: FALSE
L13: FALSE
L14: FALSE
L15: FALSE
L16: FALSE
L17: FALSE
L18: FALSE
L19: FALSE
L20: FALSE
... L25: FALSE
J26: Cumulative (Semester 1)
J27: Grade Point Average | M27: Total Credits
B28: Classes (Semester 2) | J28: {=GPA({K8:K25,M8:M25,O8:O25},1,2)} -> Loading... | M28: {=CREDITSSUM({K8:K25,M8:M25},1,2)} -> Loading...
B29: Course Title | K29: Credits | L29: Met Requirements | M29: Grade | O29: Weight
L31: FALSE
L32: FALSE
L33: FALSE
L34: FALSE
L35: FALSE
L36: FALSE
L37: FALSE
L38: FALSE
L39: FALSE
L40: FALSE
L41: FALSE
L42: FALSE
... L47: FALSE
J48: Cumulative (Semester 2)
J49: Grade Point Average | M49: Total Credits
B50: MAP Scores | J50: {=GPA({K30:K47,M30:M47,O30:O47},1,2)} -> Loading... | M50: {=CREDITSSUM({K30:K47,M30:M47},1,2)} -> Loading...
...

Sheet 2nd Grade (Semester)
C1: Student Information | I1: School Information
B2: Grade Scale | C2: Full Name | F2: ='Getting Started'!$G$10 | I2: Name | K2: ='Getting Started'!$I$10
B3: 0-4 | C3: Date of Birth | F3: ='Getting Started'!$G$11 | I3: Phone Number | K3: ='Getting Started'!$I$11
C4: Parent/Guardian | F4: ='Getting Started'!$G$12 | I4: Address | K4: ='Getting Started'!$I$12
C5: Expected Graduation | F5: ='Getting Started'!$G$14 | I5: Email Address | K5: ='Getting Started'!$I$14
B6: Classes (Semester 1)
B7: Course Title | K7: Credits | L7: Met Requirements | M7: Grade | O7: Weight
L9: FALSE
L10: FALSE
L11: FALSE
L12: FALSE
L13: FALSE
L14: FALSE
L15: FALSE
L16: FALSE
L17: FALSE
L18: FALSE
L19: FALSE
L20: FALSE
... L25: FALSE
J26: Cumulative (Semester 1)
J27: Grade Point Average | M27: Total Credits
B28: Classes (Semester 2) | J28: {=GPA({K8:K25,M8:M25,O8:O25},1,2)} -> Loading... | M28: {=CREDITSSUM({K8:K25,M8:M25},1,2)} -> Loading...
B29: Course Title | K29: Credits | L29: Met Requirements | M29: Grade | O29: Weight
L31: FALSE
L32: FALSE
L33: FALSE
L34: FALSE
L35: FALSE
L36: FALSE
L37: FALSE
L38: FALSE
L39: FALSE
L40: FALSE
L41: FALSE
L42: FALSE
... L47: FALSE
J48: Cumulative (Semester 2)
J49: Grade Point Average | M49: Total Credits
B50: MAP Scores | J50: {=GPA({K30:K47,M30:M47,O30:O47},1,2)} -> Loading... | M50: {=CREDITSSUM({K30:K47,M30:M47},1,2)} -> Loading...
...

Sheet 3rd Grade (Semester)
C1: Student Information | I1: School Information
B2: Grade Scale | C2: Full Name | F2: ='Getting Started'!$G$10 | I2: Name | K2: ='Getting Started'!$I$10
B3: 0-4 | C3: Date of Birth | F3: ='Getting Started'!$G$11 | I3: Phone Number | K3: ='Getting Started'!$I$11
C4: Parent/Guardian | F4: ='Getting Started'!$G$12 | I4: Address | K4: ='Getting Started'!$I$12
C5: Expected Graduation | F5: ='Getting Started'!$G$14 | I5: Email Address | K5: ='Getting Started'!$I$14
B6: Classes (Semester 1)
B7: Course Title | K7: Credits | L7: Met Requirements | M7: Grade | O7: Weight
L9: FALSE
L10: FALSE
L11: FALSE
L12: FALSE
L13: FALSE
L14: FALSE
L15: FALSE
L16: FALSE
L17: FALSE
L18: FALSE
L19: FALSE
L20: FALSE
... L25: FALSE
J26: Cumulative (Semester 1)
J27: Grade Point Average | M27: Total Credits
B28: Classes (Semester 2) | J28: {=GPA({K8:K25,M8:M25,O8:O25},1,2)} -> Loading... | M28: {=CREDITSSUM({K8:K25,M8:M25},1,2)} -> Loading...
B29: Course Title | K29: Credits | L29: Met Requirements | M29: Grade | O29: Weight
L31: FALSE
L32: FALSE
L33: FALSE
L34: FALSE
L35: FALSE
L36: FALSE
L37: FALSE
L38: FALSE
L39: FALSE
L40: FALSE
L41: FALSE
L42: FALSE
... L47: FALSE
J48: Cumulative (Semester 2)
J49: Grade Point Average | M49: Total Credits
B50: MAP Scores | J50: {=GPA({K30:K47,M30:M47,O30:O47},1,2)} -> Loading... | M50: {=CREDITSSUM({K30:K47,M30:M47},1,2)} -> Loading...
...

Sheet 4th Grade (Semester)
C1: Student Information | I1: School Information
B2: Grade Scale | C2: Full Name | F2: ='Getting Started'!$G$10 | I2: Name | K2: ='Getting Started'!$I$10
B3: 0-4 | C3: Date of Birth | F3: ='Getting Started'!$G$11 | I3: Phone Number | K3: ='Getting Started'!$I$11
C4: Parent/Guardian | F4: ='Getting Started'!$G$12 | I4: Address | K4: ='Getting Started'!$I$12
C5: Expected Graduation | F5: ='Getting Started'!$G$14 | I5: Email Address | K5: ='Getting Started'!$I$14
B6: Classes (Semester 1)
B7: Course Title | K7: Credits | L7: Met Requirements | M7: Grade | O7: Weight
L9: FALSE
L10: FALSE
L11: FALSE
L12: FALSE
L13: FALSE
L14: FALSE
L15: FALSE
L16: FALSE
L17: FALSE
L18: FALSE
L19: FALSE
L20: FALSE
... L25: FALSE
J26: Cumulative (Semester 1)
J27: Grade Point Average | M27: Total Credits
B28: Classes (Semester 2) | J28: {=GPA({K8:K25,M8:M25,O8:O25},1,2)} -> Loading... | M28: {=CREDITSSUM({K8:K25,M8:M25},1,2)} -> Loading...
B29: Course Title | K29: Credits | L29: Met Requirements | M29: Grade | O29: Weight
L31: FALSE
L32: FALSE
L33: FALSE
L34: FALSE
L35: FALSE
L36: FALSE
L37: FALSE
L38: FALSE
L39: FALSE
L40: FALSE
L41: FALSE
L42: FALSE
... L47: FALSE
J48: Cumulative (Semester 2)
J49: Grade Point Average | M49: Total Credits
B50: MAP Scores | J50: {=GPA({K30:K47,M30:M47,O30:O47},1,2)} -> Loading... | M50: {=CREDITSSUM({K30:K47,M30:M47},1,2)} -> Loading...
...

Sheet 5th Grade (Semester)
C1: Student Information | I1: School Information
B2: Grade Scale | C2: Full Name | F2: ='Getting Started'!$G$10 | I2: Name | K2: ='Getting Started'!$I$10
B3: 0-4 | C3: Date of Birth | F3: ='Getting Started'!$G$11 | I3: Phone Number | K3: ='Getting Started'!$I$11
C4: Parent/Guardian | F4: ='Getting Started'!$G$12 | I4: Address | K4: ='Getting Started'!$I$12
C5: Expected Graduation | F5: ='Getting Started'!$G$14 | I5: Email Address | K5: ='Getting Started'!$I$14
B6: Classes (Semester 1)
B7: Course Title | K7: Credits | L7: Met Requirements | M7: Grade | O7: Weight
L9: FALSE
L10: FALSE
L11: FALSE
L12: FALSE
L13: FALSE
L14: FALSE
L15: FALSE
L16: FALSE
L17: FALSE
L18: FALSE
L19: FALSE
L20: FALSE
... L25: FALSE
J26: Cumulative (Semester 1)
J27: Grade Point Average | M27: Total Credits
B28: Classes (Semester 2) | J28: {=GPA({K8:K25,M8:M25,O8:O25},1,2)} -> Loading... | M28: {=CREDITSSUM({K8:K25,M8:M25},1,2)} -> Loading...
B29: Course Title | K29: Credits | L29: Met Requirements | M29: Grade | O29: Weight
L31: FALSE
L32: FALSE
L33: FALSE
L34: FALSE
L35: FALSE
L36: FALSE
L37: FALSE
L38: FALSE
L39: FALSE
L40: FALSE
L41: FALSE
L42: FALSE
... L47: FALSE
J48: Cumulative (Semester 2)
J49: Grade Point Average | M49: Total Credits
B50: MAP Scores | J50: {=GPA({K30:K47,M30:M47,O30:O47},1,2)} -> Loading... | M50: {=CREDITSSUM({K30:K47,M30:M47},1,2)} -> Loading...
...

Sheet 6th Grade (Semester)
C1: Student Information | I1: School Information
B2: Grade Scale | C2: Full Name | F2: ='Getting Started'!$G$10 | I2: Name | K2: ='Getting Started'!$I$10
B3: 0-4 | C3: Date of Birth | F3: ='Getting Started'!$G$11 | I3: Phone Number | K3: ='Getting Started'!$I$11
C4: Parent/Guardian | F4: ='Getting Started'!$G$12 | I4: Address | K4: ='Getting Started'!$I$12
C5: Expected Graduation | F5: ='Getting Started'!$G$14 | I5: Email Address | K5: ='Getting Started'!$I$14
B6: Classes (Semester 1)
B7: Course Title | K7: Credits | L7: Met Requirements | M7: Grade | O7: Weight
L9: FALSE
L10: FALSE
L11: FALSE
L12: FALSE
L13: FALSE
L14: FALSE
L15: FALSE
L16: FALSE
L17: FALSE
L18: FALSE
L19: FALSE
L20: FALSE
... L25: FALSE
J26: Cumulative (Semester 1)
J27: Grade Point Average | M27: Total Credits
B28: Classes (Semester 2) | J28: {=GPA({K8:K25,M8:M25,O8:O25},1,2)} -> Loading... | M28: {=CREDITSSUM({K8:K25,M8:M25},1,2)} -> Loading...
B29: Course Title | K29: Credits | L29: Met Requirements | M29: Grade | O29: Weight
L31: FALSE
L32: FALSE
L33: FALSE
L34: FALSE
L35: FALSE
L36: FALSE
L37: FALSE
L38: FALSE
L39: FALSE
L40: FALSE
L41: FALSE
L42: FALSE
... L47: FALSE
J48: Cumulative (Semester 2)
J49: Grade Point Average | M49: Total Credits
B50: MAP Scores | J50: {=GPA({K30:K47,M30:M47,O30:O47},1,2)} -> Loading... | M50: {=CREDITSSUM({K30:K47,M30:M47},1,2)} -> Loading...
...

Sheet 7th Grade (Semester)
C1: Student Information | I1: School Information
B2: Grade Scale | C2: Full Name | F2: ='Getting Started'!$G$10 | I2: Name | K2: ='Getting Started'!$I$10
B3: 0-4 | C3: Date of Birth | F3: ='Getting Started'!$G$11 | I3: Phone Number | K3: ='Getting Started'!$I$11
C4: Parent/Guardian | F4: ='Getting Started'!$G$12 | I4: Address | K4: ='Getting Started'!$I$12
C5: Expected Graduation | F5: ='Getting Started'!$G$14 | I5: Email Address | K5: ='Getting Started'!$I$14
B6: Classes (Semester 1)
B7: Course Title | K7: Credits | L7: Met Requirements | M7: Grade | O7: Weight
L9: FALSE
L10: FALSE
L11: FALSE
L12: FALSE
L13: FALSE
L14: FALSE
L15: FALSE
L16: FALSE
L17: FALSE
L18: FALSE
L19: FALSE
L20: FALSE
... L25: FALSE
J26: Cumulative (Semester 1)
J27: Grade Point Average | M27: Total Credits
B28: Classes (Semester 2) | J28: {=GPA({K8:K25,M8:M25,O8:O25},1,2)} -> Loading... | M28: {=CREDITSSUM({K8:K25,M8:M25},1,2)} -> Loading...
B29: Course Title | K29: Credits | L29: Met Requirements | M29: Grade | O29: Weight
L31: FALSE
L32: FALSE
L33: FALSE
L34: FALSE
L35: FALSE
L36: FALSE
L37: FALSE
L38: FALSE
L39: FALSE
L40: FALSE
L41: FALSE
L42: FALSE
... L47: FALSE
J48: Cumulative (Semester 2)
J49: Grade Point Average | M49: Total Credits
B50: MAP Scores | J50: {=GPA({K30:K47,M30:M47,O30:O47},1,2)} -> Loading... | M50: {=CREDITSSUM({K30:K47,M30:M47},1,2)} -> Loading...
...

Sheet 8th Grade (Semester)
C1: Student Information | I1: School Information
B2: Grade Scale | C2: Full Name | F2: ='Getting Started'!$G$10 | I2: Name | K2: ='Getting Started'!$I$10
B3: 0-4 | C3: Date of Birth | F3: ='Getting Started'!$G$11 | I3: Phone Number | K3: ='Getting Started'!$I$11
C4: Parent/Guardian | F4: ='Getting Started'!$G$12 | I4: Address | K4: ='Getting Started'!$I$12
C5: Expected Graduation | F5: ='Getting Started'!$G$14 | I5: Email Address | K5: ='Getting Started'!$I$14
B6: Classes (Semester 1)
B7: Course Title | K7: Credits | L7: Met Requirements | M7: Grade | O7: Weight
L9: FALSE
L10: FALSE
L11: FALSE
L12: FALSE
L13: FALSE
L14: FALSE
L15: FALSE
L16: FALSE
L17: FALSE
L18: FALSE
L19: FALSE
L20: FALSE
... L25: FALSE
J26: Cumulative (Semester 1)
J27: Grade Point Average | M27: Total Credits
B28: Classes (Semester 2) | J28: {=GPA({K8:K25,M8:M25,O8:O25},1,2)} -> Loading... | M28: {=CREDITSSUM({K8:K25,M8:M25},1,2)} -> Loading...
B29: Course Title | K29: Credits | L29: Met Requirements | M29: Grade | O29: Weight
L31: FALSE
L32: FALSE
L33: FALSE
L34: FALSE
L35: FALSE
L36: FALSE
L37: FALSE
L38: FALSE
L39: FALSE
L40: FALSE
L41: FALSE
L42: FALSE
... L47: FALSE
J48: Cumulative (Semester 2)
J49: Grade Point Average | M49: Total Credits
B50: MAP Scores | J50: {=GPA({K30:K47,M30:M47,O30:O47},1,2)} -> Loading... | M50: {=CREDITSSUM({K30:K47,M30:M47},1,2)} -> Loading...
...

Sheet 9th Grade (Semester)
C1: Student Information | I1: School Information
B2: Grade Scale
B3: 0-4 | C3: Full Name | F3: ='Getting Started'!$G$10 | I3: Name | K3: ='Getting Started'!$I$10
B4: Cumulative GPA | C4: Date of Birth | F4: ='Getting Started'!$G$11 | I4: Phone Number | K4: ='Getting Started'!$I$11
B5: =J57 -> Loading... | C5: Parent/Guardian | F5: ='Getting Started'!$G$12 | I5: Address | K5: ='Getting Started'!$I$12
B6: Total Credits
B7: =M57 -> Loading... | C7: Expected Graduation | F7: ='Getting Started'!$G$14 | I7: Email Address | K7: ='Getting Started'!$I$14
B8: Classes (Semester 1)
B9: Course Title | K9: Credits | L9: Met Requirements | M9: Grade | O9: Weight
L11: FALSE
L12: FALSE
L13: FALSE
L14: FALSE
L15: FALSE
L16: FALSE
L17: FALSE
L18: FALSE
L19: FALSE
L20: FALSE
L21: FALSE
L22: FALSE
... L27: FALSE
B28: Notes | J28: Cumulative (Semester 1)
J29: Grade Point Average | M29: Total Credits
B30: Classes (Semester 2) | J30: {=GPA({K10:K27,M10:M27,O10:O27},1,2)} -> Loading... | M30: {=CREDITSSUM({K10:K27,M10:M27},1,2)} -> Loading...
B31: Course Title | K31: Credits | L31: Met Requirements | M31: Grade | O31: Weight
L33: FALSE
L34: FALSE
L35: FALSE
L36: FALSE
L37: FALSE
L38: FALSE
L39: FALSE
L40: FALSE
L41: FALSE
L42: FALSE
L43: FALSE
L44: FALSE
... L49: FALSE
B50: Notes | J50: Cumulative (Semester 2)
...

Sheet 10th Grade (Semester)
C1: Student Information | I1: School Information
B2: Grade Scale
B3: 0-4 | C3: Full Name | F3: ='Getting Started'!$G$10 | I3: Name | K3: ='Getting Started'!$I$10
B4: Cumulative GPA | C4: Date of Birth | F4: ='Getting Started'!$G$11 | I4: Phone Number | K4: ='Getting Started'!$I$11
B5: {=GPA({'9th Grade (Semester)'!K10:K27,'9th Grade (Semester)'!M10:M27,'9th Grade (Semester)'!O10:O27;'9th Grade (Semester)'!K32:K49,'9th Grade (Semester)'!M32:M49,'9th Grade (Semester)'!O32:O49;K10:K27,M10:M27,O10:O27;K32:K49,M32:M49,O32:O49},1,2)} -> Loading... | C5: Parent/Guardian | F5: ='Getting Started'!$G$12 | I5: Address | K5: ='Getting Started'!$I$12
B6: Total Credits
B7: =IF('9th Grade (Semester)'!B7+M57 = 0, "", '9th Grade (Semester)'!B7+M57) -> Loading... | C7: Expected Graduation | F7: ='Getting Started'!$G$14 | I7: Email Address | K7: ='Getting Started'!$I$14
B8: Classes (Semester 1)
B9: Course Title | K9: Credits | L9: Met Requirements | M9: Grade | O9: Weight
L11: FALSE
L12: FALSE
L13: FALSE
L14: FALSE
L15: FALSE
L16: FALSE
L17: FALSE
L18: FALSE
L19: FALSE
L20: FALSE
L21: FALSE
L22: FALSE
... L27: FALSE
B28: Notes | J28: Cumulative (Semester 1)
J29: Grade Point Average | M29: Total Credits
B30: Classes (Semester 2) | J30: {=GPA({K10:K27,M10:M27,O10:O27},1,2)} -> Loading... | M30: {=CREDITSSUM({K10:K27,M10:M27},1,2)} -> Loading...
B31: Course Title | K31: Credits | L31: Met Requirements | M31: Grade | O31: Weight
L33: FALSE
L34: FALSE
L35: FALSE
L36: FALSE
L37: FALSE
L38: FALSE
L39: FALSE
L40: FALSE
L41: FALSE
L42: FALSE
L43: FALSE
L44: FALSE
... L49: FALSE
B50: Notes | J50: Cumulative (Semester 2)
...

Sheet 11th Grade (Semester)
C1: Student Information | I1: School Information
B2: Grade Scale
B3: 0-4 | C3: Full Name | F3: ='Getting Started'!$G$10 | I3: Name | K3: ='Getting Started'!$I$10
B4: Cumulative GPA | C4: Date of Birth | F4: ='Getting Started'!$G$11 | I4: Phone Number | K4: ='Getting Started'!$I$11
B5: {=GPA({'9th Grade (Semester)'!K10:K27,'9th Grade (Semester)'!M10:M27,'9th Grade (Semester)'!O10:O27;'9th Grade (Semester)'!K32:K49,'9th Grade (Semester)'!M32:M49,'9th Grade (Semester)'!O32:O49;'10th Grade (Semester)'!K10:K27,'10th Grade (Semester)'!M10:M27,'10th Grade (Semester)'!O10:O27;'10th Grade (Semester)'!K32:K49,'10th Grade (Semester)'!M32:M49,'10th Grade (Semester)'!O32:O49;K10:K27,M10:M27,O10:O27;K32:K49,M32:M49,O32:O49},1,2)} -> Loading... | C5: Parent/Guardian | F5: ='Getting Started'!$G$12 | I5: Address | K5: ='Getting Started'!$I$12
B6: Total Credits
B7: =IF('10th Grade (Semester)'!B7+M57 = 0, "", '10th Grade (Semester)'!B7+M57) -> Loading... | C7: Expected Graduation | F7: ='Getting Started'!$G$14 | I7: Email Address | K7: ='Getting Started'!$I$14
B8: Classes (Semester 1)
B9: Course Title | K9: Credits | L9: Met Requirements | M9: Grade | O9: Weight
L11: FALSE
L12: FALSE
L13: FALSE
L14: FALSE
L15: FALSE
L16: FALSE
L17: FALSE
L18: FALSE
L19: FALSE
L20: FALSE
L21: FALSE
L22: FALSE
... L27: FALSE
B28: Notes | J28: Cumulative (Semester 1)
J29: Grade Point Average | M29: Total Credits
B30: Classes (Semester 2) | J30: {=GPA({K10:K27,M10:M27,O10:O27},1,2)} -> Loading... | M30: {=CREDITSSUM({K10:K27,M10:M27},1,2)} -> Loading...
B31: Course Title | K31: Credits | L31: Met Requirements | M31: Grade | O31: Weight
L33: FALSE
L34: FALSE
L35: FALSE
L36: FALSE
L37: FALSE
L38: FALSE
L39: FALSE
L40: FALSE
L41: FALSE
L42: FALSE
L43: FALSE
L44: FALSE
... L49: FALSE
B50: Notes | J50: Cumulative (Semester 2)
...

Sheet 12th Grade (Semester)
C1: Student Information | I1: School Information
B2: Grade Scale
B3: 0-4 | C3: Full Name | F3: ='Getting Started'!$G$10 | I3: Name | K3: ='Getting Started'!$I$10
B4: Cumulative GPA | C4: Date of Birth | F4: ='Getting Started'!$G$11 | I4: Phone Number | K4: ='Getting Started'!$I$11
B5: {=GPA({'9th Grade (Semester)'!K10:K27,'9th Grade (Semester)'!M10:M27,'9th Grade (Semester)'!O10:O27;'9th Grade (Semester)'!K32:K49,'9th Grade (Semester)'!M32:M49,'9th Grade (Semester)'!O32:O49;'10th Grade (Semester)'!K10:K27,'10th Grade (Semester)'!M10:M27,'10th Grade (Semester)'!O10:O27;'10th Grade (Semester)'!K32:K49,'10th Grade (Semester)'!M32:M49,'10th Grade (Semester)'!O32:O49;'11th Grade (Semester)'!K10:K27,'11th Grade (Semester)'!M10:M27,'11th Grade (Semester)'!O10:O27;'11th Grade (Semester)'!K32:K49,'11th Grade (Semester)'!M32:M49,'11th Grade (Semester)'!O32:O49;K10:K27,M10:M27,O10:O27;K32:K49,M32:M49,O32:O49},1,2)} -> Loading... | C5: Parent/Guardian | F5: ='Getting Started'!$G$12 | I5: Address | K5: ='Getting Started'!$I$12
B6: Total Credits
B7: =IF('11th Grade (Semester)'!B7+M57 = 0, "", '11th Grade (Semester)'!B7+M57) -> Loading... | C7: Expected Graduation | F7: ='Getting Started'!$G$14 | I7: Email Address | K7: ='Getting Started'!$I$14
B8: Classes (Semester 1)
B9: Course Title | K9: Credits | L9: Met Requirements | M9: Grade | O9: Weight
L11: FALSE
L12: FALSE
L13: FALSE
L14: FALSE
L15: FALSE
L16: FALSE
L17: FALSE
L18: FALSE
L19: FALSE
L20: FALSE
L21: FALSE
L22: FALSE
... L27: FALSE
B28: Notes | J28: Cumulative (Semester 1)
J29: Grade Point Average | M29: Total Credits
B30: Classes (Semester 2) | J30: {=GPA({K10:K27,M10:M27,O10:O27},1,2)} -> Loading... | M30: {=CREDITSSUM({K10:K27,M10:M27},1,2)} -> Loading...
B31: Course Title | K31: Credits | L31: Met Requirements | M31: Grade | O31: Weight
L33: FALSE
L34: FALSE
L35: FALSE
L36: FALSE
L37: FALSE
L38: FALSE
L39: FALSE
L40: FALSE
L41: FALSE
L42: FALSE
L43: FALSE
L44: FALSE
... L49: FALSE
B50: Notes | J50: Cumulative (Semester 2)
...

Sheet Kindergarten (Trimester)
C1: Student Information | I1: School Information
B2: Grade Scale | C2: Full Name | F2: ='Getting Started'!$G$10 | I2: Name | K2: ='Getting Started'!$I$10
B3: 0-4 | C3: Date of Birth | F3: ='Getting Started'!$G$11 | I3: Phone Number | K3: ='Getting Started'!$I$11
C4: Parent/Guardian | F4: ='Getting Started'!$G$12 | I4: Address | K4: ='Getting Started'!$I$12
C5: Expected Graduation | F5: ='Getting Started'!$G$14 | I5: Email Address | K5: ='Getting Started'!$I$14
B6: Classes (Trimester 1)
B7: Course Title | K7: Credits | L7: Met Requirements | M7: Grade | O7: Weight
L9: FALSE
L10: FALSE
L11: FALSE
L12: FALSE
L13: FALSE
L14: FALSE
L15: FALSE
L16: FALSE
L17: FALSE
J18: Cumulative (Trimester 1)
J19: Grade Point Average | M19: Total Credits
B20: Classes (Trimester 2) | J20: {=GPA({K8:K17,M8:M17,O8:O17},1,2)} -> Loading... | M20: {=CREDITSSUM({K8:K17,M8:M17},1,2)} -> Loading...
B21: Course Title | K21: Credits | L21: Met Requirements | M21: Grade | O21: Weight
L23: FALSE
L24: FALSE
L25: FALSE
L26: FALSE
L27: FALSE
L28: FALSE
L29: FALSE
L30: FALSE
L31: FALSE
J32: Cumulative (Trimester 2)
J33: Grade Point Average | M33: Total Credits
B34: Classes (Trimester 3) | J34: {=GPA({K22:K31,M22:M31,O22:O31},1,2)} -> Loading... | M34: {=CREDITSSUM({K22:K31,M22:M31},1,2)} -> Loading...
B35: Course Title | K35: Credits | L35: Met Requirements | M35: Grade | O35: Weight
L37: FALSE
L38: FALSE
L39: FALSE
L40: FALSE
L41: FALSE
L42: FALSE
L43: FALSE
...

Sheet 1st Grade (Trimester)
C1: Student Information | I1: School Information
B2: Grade Scale | C2: Full Name | F2: ='Getting Started'!$G$10 | I2: Name | K2: ='Getting Started'!$I$10
B3: 0-4 | C3: Date of Birth | F3: ='Getting Started'!$G$11 | I3: Phone Number | K3: ='Getting Started'!$I$11
C4: Parent/Guardian | F4: ='Getting Started'!$G$12 | I4: Address | K4: ='Getting Started'!$I$12
C5: Expected Graduation | F5: ='Getting Started'!$G$14 | I5: Email Address | K5: ='Getting Started'!$I$14
B6: Classes (Trimester 1)
B7: Course Title | K7: Credits | L7: Met Requirements | M7: Grade | O7: Weight
L9: FALSE
L10: FALSE
L11: FALSE
L12: FALSE
L13: FALSE
L14: FALSE
L15: FALSE
L16: FALSE
L17: FALSE
J18: Cumulative (Trimester 1)
J19: Grade Point Average | M19: Total Credits
B20: Classes (Trimester 2) | J20: {=GPA({K8:K17,M8:M17,O8:O17},1,2)} -> Loading... | M20: {=CREDITSSUM({K8:K17,M8:M17},1,2)} -> Loading...
B21: Course Title | K21: Credits | L21: Met Requirements | M21: Grade | O21: Weight
L23: FALSE
L24: FALSE
L25: FALSE
L26: FALSE
L27: FALSE
L28: FALSE
L29: FALSE
L30: FALSE
L31: FALSE
J32: Cumulative (Trimester 2)
J33: Grade Point Average | M33: Total Credits
B34: Classes (Trimester 3) | J34: {=GPA({K22:K31,M22:M31,O22:O31},1,2)} -> Loading... | M34: {=CREDITSSUM({K22:K31,M22:M31},1,2)} -> Loading...
B35: Course Title | K35: Credits | L35: Met Requirements | M35: Grade | O35: Weight
L37: FALSE
L38: FALSE
L39: FALSE
L40: FALSE
L41: FALSE
L42: FALSE
L43: FALSE
...

Sheet 2nd Grade (Trimester)
C1: Student Information | I1: School Information
B2: Grade Scale | C2: Full Name | F2: ='Getting Started'!$G$10 | I2: Name | K2: ='Getting Started'!$I$10
B3: 0-4 | C3: Date of Birth | F3: ='Getting Started'!$G$11 | I3: Phone Number | K3: ='Getting Started'!$I$11
C4: Parent/Guardian | F4: ='Getting Started'!$G$12 | I4: Address | K4: ='Getting Started'!$I$12
C5: Expected Graduation | F5: ='Getting Started'!$G$14 | I5: Email Address | K5: ='Getting Started'!$I$14
B6: Classes (Trimester 1)
B7: Course Title | K7: Credits | L7: Met Requirements | M7: Grade | O7: Weight
L9: FALSE
L10: FALSE
L11: FALSE
L12: FALSE
L13: FALSE
L14: FALSE
L15: FALSE
L16: FALSE
L17: FALSE
J18: Cumulative (Trimester 1)
J19: Grade Point Average | M19: Total Credits
B20: Classes (Trimester 2) | J20: {=GPA({K8:K17,M8:M17,O8:O17},1,2)} -> Loading... | M20: {=CREDITSSUM({K8:K17,M8:M17},1,2)} -> Loading...
B21: Course Title | K21: Credits | L21: Met Requirements | M21: Grade | O21: Weight
L23: FALSE
L24: FALSE
L25: FALSE
L26: FALSE
L27: FALSE
L28: FALSE
L29: FALSE
L30: FALSE
L31: FALSE
J32: Cumulative (Trimester 2)
J33: Grade Point Average | M33: Total Credits
B34: Classes (Trimester 3) | J34: {=GPA({K22:K31,M22:M31,O22:O31},1,2)} -> Loading... | M34: {=CREDITSSUM({K22:K31,M22:M31},1,2)} -> Loading...
B35: Course Title | K35: Credits | L35: Met Requirements | M35: Grade | O35: Weight
L37: FALSE
L38: FALSE
L39: FALSE
L40: FALSE
L41: FALSE
L42: FALSE
L43: FALSE
...

Sheet 3rd Grade (Trimester)
C1: Student Information | I1: School Information
B2: Grade Scale | C2: Full Name | F2: ='Getting Started'!$G$10 | I2: Name | K2: ='Getting Started'!$I$10
B3: 0-4 | C3: Date of Birth | F3: ='Getting Started'!$G$11 | I3: Phone Number | K3: ='Getting Started'!$I$11
C4: Parent/Guardian | F4: ='Getting Started'!$G$12 | I4: Address | K4: ='Getting Started'!$I$12
C5: Expected Graduation | F5: ='Getting Started'!$G$14 | I5: Email Address | K5: ='Getting Started'!$I$14
B6: Classes (Trimester 1)
B7: Course Title | K7: Credits | L7: Met Requirements | M7: Grade | O7: Weight
L9: FALSE
L10: FALSE
L11: FALSE
L12: FALSE
L13: FALSE
L14: FALSE
L15: FALSE
L16: FALSE
L17: FALSE
J18: Cumulative (Trimester 1)
J19: Grade Point Average | M19: Total Credits
B20: Classes (Trimester 2) | J20: {=GPA({K8:K17,M8:M17,O8:O17},1,2)} -> Loading... | M20: {=CREDITSSUM({K8:K17,M8:M17},1,2)} -> Loading...
B21: Course Title | K21: Credits | L21: Met Requirements | M21: Grade | O21: Weight
L23: FALSE
L24: FALSE
L25: FALSE
L26: FALSE
L27: FALSE
L28: FALSE
L29: FALSE
L30: FALSE
L31: FALSE
J32: Cumulative (Trimester 2)
J33: Grade Point Average | M33: Total Credits
B34: Classes (Trimester 3) | J34: {=GPA({K22:K31,M22:M31,O22:O31},1,2)} -> Loading... | M34: {=CREDITSSUM({K22:K31,M22:M31},1,2)} -> Loading...
B35: Course Title | K35: Credits | L35: Met Requirements | M35: Grade | O35: Weight
L37: FALSE
L38: FALSE
L39: FALSE
L40: FALSE
L41: FALSE
L42: FALSE
L43: FALSE
...

Sheet 4th Grade (Trimester)
C1: Student Information | I1: School Information
B2: Grade Scale | C2: Full Name | F2: ='Getting Started'!$G$10 | I2: Name | K2: ='Getting Started'!$I$10
B3: 0-4 | C3: Date of Birth | F3: ='Getting Started'!$G$11 | I3: Phone Number | K3: ='Getting Started'!$I$11
C4: Parent/Guardian | F4: ='Getting Started'!$G$12 | I4: Address | K4: ='Getting Started'!$I$12
C5: Expected Graduation | F5: ='Getting Started'!$G$14 | I5: Email Address | K5: ='Getting Started'!$I$14
B6: Classes (Trimester 1)
B7: Course Title | K7: Credits | L7: Met Requirements | M7: Grade | O7: Weight
L9: FALSE
L10: FALSE
L11: FALSE
L12: FALSE
L13: FALSE
L14: FALSE
L15: FALSE
L16: FALSE
L17: FALSE
J18: Cumulative (Trimester 1)
J19: Grade Point Average | M19: Total Credits
B20: Classes (Trimester 2) | J20: {=GPA({K8:K17,M8:M17,O8:O17},1,2)} -> Loading... | M20: {=CREDITSSUM({K8:K17,M8:M17},1,2)} -> Loading...
B21: Course Title | K21: Credits | L21: Met Requirements | M21: Grade | O21: Weight
L23: FALSE
L24: FALSE
L25: FALSE
L26: FALSE
L27: FALSE
L28: FALSE
L29: FALSE
L30: FALSE
L31: FALSE
J32: Cumulative (Trimester 2)
J33: Grade Point Average | M33: Total Credits
B34: Classes (Trimester 3) | J34: {=GPA({K22:K31,M22:M31,O22:O31},1,2)} -> Loading... | M34: {=CREDITSSUM({K22:K31,M22:M31},1,2)} -> Loading...
B35: Course Title | K35: Credits | L35: Met Requirements | M35: Grade | O35: Weight
L37: FALSE
L38: FALSE
L39: FALSE
L40: FALSE
L41: FALSE
L42: FALSE
L43: FALSE
...

Sheet 5th Grade (Trimester)
C1: Student Information | I1: School Information
B2: Grade Scale | C2: Full Name | F2: ='Getting Started'!$G$10 | I2: Name | K2: ='Getting Started'!$I$10
B3: 0-4 | C3: Date of Birth | F3: ='Getting Started'!$G$11 | I3: Phone Number | K3: ='Getting Started'!$I$11
C4: Parent/Guardian | F4: ='Getting Started'!$G$12 | I4: Address | K4: ='Getting Started'!$I$12
C5: Expected Graduation | F5: ='Getting Started'!$G$14 | I5: Email Address | K5: ='Getting Started'!$I$14
B6: Classes (Trimester 1)
B7: Course Title | K7: Credits | L7: Met Requirements | M7: Grade | O7: Weight
L9: FALSE
L10: FALSE
L11: FALSE
L12: FALSE
L13: FALSE
L14: FALSE
L15: FALSE
L16: FALSE
L17: FALSE
J18: Cumulative (Trimester 1)
J19: Grade Point Average | M19: Total Credits
B20: Classes (Trimester 2) | J20: {=GPA({K8:K17,M8:M17,O8:O17},1,2)} -> Loading... | M20: {=CREDITSSUM({K8:K17,M8:M17},1,2)} -> Loading...
B21: Course Title | K21: Credits | L21: Met Requirements | M21: Grade | O21: Weight
L23: FALSE
L24: FALSE
L25: FALSE
L26: FALSE
L27: FALSE
L28: FALSE
L29: FALSE
L30: FALSE
L31: FALSE
J32: Cumulative (Trimester 2)
J33: Grade Point Average | M33: Total Credits
B34: Classes (Trimester 3) | J34: {=GPA({K22:K31,M22:M31,O22:O31},1,2)} -> Loading... | M34: {=CREDITSSUM({K22:K31,M22:M31},1,2)} -> Loading...
B35: Course Title | K35: Credits | L35: Met Requirements | M35: Grade | O35: Weight
L37: FALSE
L38: FALSE
L39: FALSE
L40: FALSE
L41: FALSE
L42: FALSE
L43: FALSE
...

Sheet 6th Grade (Trimester)
C1: Student Information | I1: School Information
B2: Grade Scale | C2: Full Name | F2: ='Getting Started'!$G$10 | I2: Name | K2: ='Getting Started'!$I$10
B3: 0-4 | C3: Date of Birth | F3: ='Getting Started'!$G$11 | I3: Phone Number | K3: ='Getting Started'!$I$11
C4: Parent/Guardian | F4: ='Getting Started'!$G$12 | I4: Address | K4: ='Getting Started'!$I$12
C5: Expected Graduation | F5: ='Getting Started'!$G$14 | I5: Email Address | K5: ='Getting Started'!$I$14
B6: Classes (Trimester 1)
B7: Course Title | K7: Credits | L7: Met Requirements | M7: Grade | O7: Weight
L9: FALSE
L10: FALSE
L11: FALSE
L12: FALSE
L13: FALSE
L14: FALSE
L15: FALSE
L16: FALSE
L17: FALSE
J18: Cumulative (Trimester 1)
J19: Grade Point Average | M19: Total Credits
B20: Classes (Trimester 2) | J20: {=GPA({K8:K17,M8:M17,O8:O17},1,2)} -> Loading... | M20: {=CREDITSSUM({K8:K17,M8:M17},1,2)} -> Loading...
B21: Course Title | K21: Credits | L21: Met Requirements | M21: Grade | O21: Weight
L23: FALSE
L24: FALSE
L25: FALSE
L26: FALSE
L27: FALSE
L28: FALSE
L29: FALSE
L30: FALSE
L31: FALSE
J32: Cumulative (Trimester 2)
J33: Grade Point Average | M33: Total Credits
B34: Classes (Trimester 3) | J34: {=GPA({K22:K31,M22:M31,O22:O31},1,2)} -> Loading... | M34: {=CREDITSSUM({K22:K31,M22:M31},1,2)} -> Loading...
B35: Course Title | K35: Credits | L35: Met Requirements | M35: Grade | O35: Weight
L37: FALSE
L38: FALSE
L39: FALSE
L40: FALSE
L41: FALSE
L42: FALSE
L43: FALSE
...

Sheet 7th Grade (Trimester)
C1: Student Information | I1: School Information
B2: Grade Scale | C2: Full Name | F2: ='Getting Started'!$G$10 | I2: Name | K2: ='Getting Started'!$I$10
B3: 0-4 | C3: Date of Birth | F3: ='Getting Started'!$G$11 | I3: Phone Number | K3: ='Getting Started'!$I$11
C4: Parent/Guardian | F4: ='Getting Started'!$G$12 | I4: Address | K4: ='Getting Started'!$I$12
C5: Expected Graduation | F5: ='Getting Started'!$G$14 | I5: Email Address | K5: ='Getting Started'!$I$14
B6: Classes (Trimester 1)
B7: Course Title | K7: Credits | L7: Met Requirements | M7: Grade | O7: Weight
L9: FALSE
L10: FALSE
L11: FALSE
L12: FALSE
L13: FALSE
L14: FALSE
L15: FALSE
L16: FALSE
L17: FALSE
J18: Cumulative (Trimester 1)
J19: Grade Point Average | M19: Total Credits
B20: Classes (Trimester 2) | J20: {=GPA({K8:K17,M8:M17,O8:O17},1,2)} -> Loading... | M20: {=CREDITSSUM({K8:K17,M8:M17},1,2)} -> Loading...
B21: Course Title | K21: Credits | L21: Met Requirements | M21: Grade | O21: Weight
L23: FALSE
L24: FALSE
L25: FALSE
L26: FALSE
L27: FALSE
L28: FALSE
L29: FALSE
L30: FALSE
L31: FALSE
J32: Cumulative (Trimester 2)
J33: Grade Point Average | M33: Total Credits
B34: Classes (Trimester 3) | J34: {=GPA({K22:K31,M22:M31,O22:O31},1,2)} -> Loading... | M34: {=CREDITSSUM({K22:K31,M22:M31},1,2)} -> Loading...
B35: Course Title | K35: Credits | L35: Met Requirements | M35: Grade | O35: Weight
L37: FALSE
L38: FALSE
L39: FALSE
L40: FALSE
L41: FALSE
L42: FALSE
L43: FALSE
...

Sheet 8th Grade (Trimester)
C1: Student Information | I1: School Information
B2: Grade Scale | C2: Full Name | F2: ='Getting Started'!$G$10 | I2: Name | K2: ='Getting Started'!$I$10
B3: 0-4 | C3: Date of Birth | F3: ='Getting Started'!$G$11 | I3: Phone Number | K3: ='Getting Started'!$I$11
C4: Parent/Guardian | F4: ='Getting Started'!$G$12 | I4: Address | K4: ='Getting Started'!$I$12
C5: Expected Graduation | F5: ='Getting Started'!$G$14 | I5: Email Address | K5: ='Getting Started'!$I$14
B6: Classes (Trimester 1)
B7: Course Title | K7: Credits | L7: Met Requirements | M7: Grade | O7: Weight
L9: FALSE
L10: FALSE
L11: FALSE
L12: FALSE
L13: FALSE
L14: FALSE
L15: FALSE
L16: FALSE
L17: FALSE
J18: Cumulative (Trimester 1)
J19: Grade Point Average | M19: Total Credits
B20: Classes (Trimester 2) | J20: {=GPA({K8:K17,M8:M17,O8:O17},1,2)} -> Loading... | M20: {=CREDITSSUM({K8:K17,M8:M17},1,2)} -> Loading...
B21: Course Title | K21: Credits | L21: Met Requirements | M21: Grade | O21: Weight
L23: FALSE
L24: FALSE
L25: FALSE
L26: FALSE
L27: FALSE
L28: FALSE
L29: FALSE
L30: FALSE
L31: FALSE
J32: Cumulative (Trimester 2)
J33: Grade Point Average | M33: Total Credits
B34: Classes (Trimester 3) | J34: {=GPA({K22:K31,M22:M31,O22:O31},1,2)} -> Loading... | M34: {=CREDITSSUM({K22:K31,M22:M31},1,2)} -> Loading...
B35: Course Title | K35: Credits | L35: Met Requirements | M35: Grade | O35: Weight
L37: FALSE
L38: FALSE
L39: FALSE
L40: FALSE
L41: FALSE
L42: FALSE
L43: FALSE
...

Sheet 9th Grade (Trimester)
C1: Student Information | I1: School Information
B2: Grade Scale
B3: 0-4 | C3: Full Name | F3: ='Getting Started'!$G$10 | I3: Name | K3: ='Getting Started'!$I$10
B4: Cumulative GPA | C4: Date of Birth | F4: ='Getting Started'!$G$11 | I4: Phone Number | K4: ='Getting Started'!$I$11
B5: =J54 -> Loading... | C5: Parent/Guardian | F5: ='Getting Started'!$G$12 | I5: Address | K5: ='Getting Started'!$I$12
B6: Total Credits
B7: =M54 -> Loading... | C7: Expected Graduation | F7: ='Getting Started'!$G$14 | I7: Email Address | K7: ='Getting Started'!$I$14
B8: Classes (Trimester 1)
B9: Course Title | K9: Credits | L9: Met Requirements | M9: Grade | O9: Weight
L11: FALSE
L12: FALSE
L13: FALSE
L14: FALSE
L15: FALSE
L16: FALSE
L17: FALSE
L18: FALSE
L19: FALSE
B20: Notes | J20: Cumulative (Trimester 1)
J21: Grade Point Average | M21: Total Credits
B22: Classes (Trimester 2) | J22: {=GPA({K10:K19,M10:M19,O10:O19},1,2)} -> Loading... | M22: {=CREDITSSUM({K10:K19,M10:M19},1,2)} -> Loading...
B23: Course Title | K23: Credits | L23: Met Requirements | M23: Grade | O23: Weight
L25: FALSE
L26: FALSE
L27: FALSE
L28: FALSE
L29: FALSE
L30: FALSE
L31: FALSE
L32: FALSE
L33: FALSE
B34: Notes | J34: Cumulative (Trimester 2)
J35: Grade Point Average | M35: Total Credits
B36: Classes (Trimester 3) | J36: {=GPA({K24:K33,M24:M33,O24:O33},1,2)} -> Loading... | M36: {=CREDITSSUM({K24:K33,M24:M33},1,2)} -> Loading...
B37: Course Title | K37: Credits | L37: Met Requirements | M37: Grade | O37: Weight
L39: FALSE
L40: FALSE
L41: FALSE
L42: FALSE
L43: FALSE
...

Sheet 10th Grade (Trimester)
C1: Student Information | I1: School Information
B2: Grade Scale
B3: 0-4 | C3: Full Name | F3: ='Getting Started'!$G$10 | I3: Name | K3: ='Getting Started'!$I$10
B4: Cumulative GPA | C4: Date of Birth | F4: ='Getting Started'!$G$11 | I4: Phone Number | K4: ='Getting Started'!$I$11
B5: {=GPA({'9th Grade (Trimester)'!K10:K19,'9th Grade (Trimester)'!M10:M19,'9th Grade (Trimester)'!O10:O19;'9th Grade (Trimester)'!K24:K33,'9th Grade (Trimester)'!M24:M33,'9th Grade (Trimester)'!O24:O33;'9th Grade (Trimester)'!K38:K47,'9th Grade (Trimester)'!M38:M47,'9th Grade (Trimester)'!O38:O47;K10:K19,M10:M19,O10:O19;K24:K33,M24:M33,O24:O33;K38:K47,M38:M47,O38:O47},1,2)} -> Loading... | C5: Parent/Guardian | F5: ='Getting Started'!$G$12 | I5: Address | K5: ='Getting Started'!$I$12
B6: Total Credits
B7: =IF('9th Grade (Trimester)'!B7+M54 = 0, "", '9th Grade (Trimester)'!B7+M54) -> Loading... | C7: Expected Graduation | F7: ='Getting Started'!$G$14 | I7: Email Address | K7: ='Getting Started'!$I$14
B8: Classes (Trimester 1)
B9: Course Title | K9: Credits | L9: Met Requirements | M9: Grade | O9: Weight
L11: FALSE
L12: FALSE
L13: FALSE
L14: FALSE
L15: FALSE
L16: FALSE
L17: FALSE
L18: FALSE
L19: FALSE
B20: Notes | J20: Cumulative (Trimester 1)
J21: Grade Point Average | M21: Total Credits
